<?xml version="1.0" encoding="utf-8"?>
<!-- EN-Revision: 7a75b854c8c52226d38397e7e8177e339fdb273f Maintainer: sergey Status: ready -->
<!-- Reviewed: no -->
<chapter xml:id="language.exceptions" xmlns="http://docbook.org/ns/docbook">
 <title>Исключения</title>
 <para>
  В PHP реализована модель исключений, аналогичная тем, что используются в других языках программирования.
  Исключение в PHP может быть выброшено (&throw;) и поймано (&catch;).
  Код может быть заключён в блок &try;, чтобы облегчить обработку потенциальных исключений.
  У каждого блока &try; должен быть как минимум один соответствующий блок &catch; или &finally;.
 </para>
 <para>
  Если выброшено исключение, а в текущей области видимости функции нет блока &catch;,
  исключение будет "подниматься" по стеку вызовов к вызывающей функции, пока не найдёт подходящий блок &catch;.
  Все блоки &finally;, которые встретятся на этом пути, будут выполнены.
  Если стек вызовов разворачивается до глобальной области видимости, не встречая подходящего блока &catch;,
  программа завершается с неисправимой ошибкой, если не был установлен глобальный обработчик исключений.
 </para>
 <para>
  Выброшенный объект должен наследовать (&instanceof;) интерфейс <interfacename>Throwable</interfacename>.
  Попытка выбросить объект, который таковым не является, приведёт к неисправимой ошибке PHP.
 </para>
 <para>
  Начиная с PHP 8.0.0, ключевое слово &throw; является выражением и может быть использовано
  в любом контексте выражения. В предыдущих версиях оно было утверждением
  и должно было располагаться в отдельной строке.
 </para>

 <sect1 annotations="chunk:false" xml:id="language.exceptions.catch">
  <title><literal>catch</literal></title>
  <para>
   Блок &catch; определяет, как реагировать на выброшенное исключение.
   Блок &catch; определяет один или несколько типов исключений или ошибок, которые он может обработать,
   и, по желанию, переменную, которой можно присвоить исключение
   (указание переменной было обязательно до версии PHP 8.0.0).
   Первый блок &catch;, с которым столкнётся выброшенное исключение или ошибка
   и соответствует типу выброшенного объекта, обработает объект.
  </para>
  <para>
   Несколько блоков &catch; могут быть использованы для перехвата различных классов исключений.
   Нормальное выполнение (когда исключение не выброшено в блоке &try;)
   будет продолжаться после последнего блока &catch;, определённого в последовательности.
   Исключения могут быть выброшены (&throw;) (или повторно выброшены) внутри блока &catch;.
   В противном случае выполнение будет продолжено после блока &catch;, который был вызван.
  </para>
  <para>
   При возникновении исключения, код, следующий за утверждением, не будет выполнен,
   а PHP попытается найти первый подходящий блок &catch;.
   Если исключение не поймано, будет выдана неисправимая ошибка PHP
   с сообщением "<literal>Uncaught Exception ...</literal>",
   если только обработчик не был определён с помощью функции <function>set_exception_handler</function>.
  </para>
  <para>
   Начиная с версии PHP 7.1.0, в блоке &catch; можно указывать несколько исключений,
   используя символ <literal>|</literal>. Это полезно, когда разные исключения
   из разных иерархий классов обрабатываются одинаково.
  </para>
  <para>
   Начиная с версии PHP 8.0.0, имя переменной для пойманного исключения является необязательным.
   Если оно не указано, блок &catch; будет выполнен,
   но не будет иметь доступа к выброшенному объекту.
  </para>
 </sect1>

 <sect1 annotations="chunk:false" xml:id="language.exceptions.finally">
  <title><literal>finally</literal></title>
  <para>
   Блок &finally; также может быть указан после или вместо блоков &catch;.
   Код в блоке &finally; всегда будет выполняться после блоков &try; и &catch;,
   независимо от того, было ли выброшено исключение
   и до возобновления нормального выполнения.
  </para>
  <para>
   Одно из заметных взаимодействий происходит между блоком &finally; и оператором &return;.
   Если оператор &return; встречается внутри блоков &try; или &catch;, блок &finally;
   всё равно будет выполнен. Более того, оператор &return; выполнится, когда встретится,
   но результат будет возвращён после выполнения блока &finally;.
   Кроме того, если блок &finally; также содержит оператор &return;,
   возвращается значение из блока &finally;.
  </para>
 </sect1>

 <sect1 annotations="chunk:false" xml:id="language.exceptions.exception-handler">
  <title>Глобальный обработчик исключений</title>
  <para>
   Если исключению разрешено распространяться на глобальную область видимости,
   оно может быть перехвачено глобальным обработчиком исключений, если он установлен.
   Функция <function>set_exception_handler</function> может задать функцию,
   которая будет вызвана вместо блока &catch;, если не будет вызван никакой другой блок.
   Эффект по сути такой же, как если бы вся программа была обёрнута в блок &try;-&catch;
   с этой функцией в качестве &catch;.
  </para>
 </sect1>

 <sect1 annotations="chunk:false" xml:id="language.exceptions.notes">
  &reftitle.notes;

  <note>
   <para>
    Внутренние функции PHP в основном используют <link linkend="ini.error-reporting">отчёт об ошибках</link>,
    только современные <link linkend="language.oop5">объектно-ориентированные</link> модули используют исключения.
    Однако ошибки можно легко перевести в исключения с помощью класса <link linkend="class.errorexception">ErrorException</link>.
    Однако эта техника работает только с исправляемыми ошибками.
   </para>
   <example>
    <title>Преобразование отчётов об ошибках в исключения</title>
    <programlisting role="php">
<![CDATA[
<?php
function exceptions_error_handler($severity, $message, $filename, $lineno) {
    throw new ErrorException($message, 0, $severity, $filename, $lineno);
}

set_error_handler('exceptions_error_handler');
?>
]]>
    </programlisting>
   </example>
  </note>
  <tip>
   <para>
    Библиотека <link linkend="intro.spl">Стандартная библиотека PHP (SPL)</link>
    предоставляет большое количество <link linkend="spl.exceptions">встроенных исключений</link>.
   </para>
  </tip>
 </sect1>

 <sect1 annotations="chunk:false" xml:id="language.exceptions.examples">
  &reftitle.examples;

  <example>
   <title>Выбрасывание исключения</title>
   <programlisting role="php">
<![CDATA[
<?php
function inverse($x) {
    if (!$x) {
        throw new Exception('Деление на ноль.');
    }
    return 1/$x;
}

try {
    echo inverse(5) . "\n";
    echo inverse(0) . "\n";
} catch (Exception $e) {
    echo 'Выброшено исключение: ',  $e->getMessage(), "\n";
}

// Продолжение выполнения
echo "Привет, мир\n";
?>
]]>
   </programlisting>
   &example.outputs;
   <screen>
<![CDATA[
0.2
Выброшено исключение: Деление на ноль.
Привет, мир
]]>
   </screen>
  </example>
  <example>
   <title>Обработка исключений с помощью блока &finally;</title>
   <programlisting role="php">
<![CDATA[
<?php
function inverse($x) {
    if (!$x) {
        throw new Exception('Деление на ноль.');
    }
    return 1/$x;
}

try {
    echo inverse(5) . "\n";
} catch (Exception $e) {
    echo 'Поймано исключение: ',  $e->getMessage(), "\n";
} finally {
    echo "Первый блок finally.\n";
}

try {
    echo inverse(0) . "\n";
} catch (Exception $e) {
    echo 'Поймано исключение: ',  $e->getMessage(), "\n";
} finally {
    echo "Второй блок finally.\n";
}

// Продолжение нормального выполнения
echo "Привет, мир\n";
?>
]]>
   </programlisting>
   &example.outputs;
   <screen>
<![CDATA[
0.2
Первый блок finally.
Поймано исключение: Деление на ноль.
Второй блок finally.
Привет, мир
]]>
   </screen>
  </example>
  <example>
   <title>Взаимодействие между блоками &finally; и &return;</title>
   <programlisting role="php">
<![CDATA[
<?php

function test() {
    try {
        throw new Exception('foo');
    } catch (Exception $e) {
        return 'catch';
    } finally {
        return 'finally';
    }
}

echo test();
?>
]]>
   </programlisting>
   &example.outputs;
   <screen>
<![CDATA[
finally
]]>
   </screen>
  </example>
  <example>
   <title>Вложенные исключения</title>
   <programlisting role="php">
<![CDATA[
<?php

class MyException extends Exception { }

class Test {
    public function testing() {
        try {
            try {
                throw new MyException('foo!');
            } catch (MyException $e) {
                // повторный выброс исключения
                throw $e;
            }
        } catch (Exception $e) {
            var_dump($e->getMessage());
        }
    }
}

$foo = new Test;
$foo->testing();

?>
]]>
   </programlisting>
   &example.outputs;
   <screen>
<![CDATA[
string(4) "foo!"
]]>
   </screen>
  </example>
  <example>
   <title>Обработка нескольких исключений в одном блоке catch</title>
   <programlisting role="php">
<![CDATA[
<?php

class MyException extends Exception { }

class MyOtherException extends Exception { }

class Test {
    public function testing() {
        try {
            throw new MyException();
        } catch (MyException | MyOtherException $e) {
            var_dump(get_class($e));
        }
    }
}

$foo = new Test;
$foo->testing();

?>
]]>
   </programlisting>
   &example.outputs;
   <screen>
<![CDATA[
string(11) "MyException"
]]>
   </screen>
  </example>
  <example>
   <title>Пример блока &catch; без указания переменной</title>
   <para>Допустимо начиная с PHP 8.0.0</para>
   <programlisting role="php">
<![CDATA[
<?php

class SpecificException extends Exception {}

function test() {
    throw new SpecificException('Ой!');
}

try {
    test();
} catch (SpecificException) {
    print "Было поймано исключение SpecificException, но нам безразлично, что у него внутри.";
}
?>
]]>
   </programlisting>
  </example>
  <example>
   <title>Throw как выражение</title>
   <para>Допустимо начиная с PHP 8.0.0</para>
   <programlisting role="php">
<![CDATA[
<?php

function test() {
    do_something_risky() or throw new Exception('Всё сломалось');
}

try {
    test();
} catch (Exception $e) {
    print $e->getMessage();
}
?>
]]>
   </programlisting>
  </example>
 </sect1>

 <sect1 xml:id="language.exceptions.extending">
  <title>Наследование исключений</title>
  <para>
   Определённый пользователем класс исключения должен быть определён, как
   класс расширяющий (наследующий) встроенный класс Exception. Ниже приведены методы и
   свойства класса Exception, доступные дочерним классам.
  </para>
  <example>
   <title>Встроенный класс Exception</title>
   <programlisting role="php">
<![CDATA[
<?php
class Exception implements Throwable
{
    protected $message = 'Unknown exception';   // сообщение об исключении
    private   $string;                          // свойство для __toString
    protected $code = 0;                        // пользовательский код исключения
    protected $file;                            // файл, в котором было выброшено исключение
    protected $line;                            // строка, в которой было выброшено исключение
    private   $trace;                           // трассировка вызовов методов и функций
    private   $previous;                        // предыдущее исключение, если исключение вложенное

    public function __construct($message = '', $code = 0, Throwable $previous = null);

    final private function __clone();           // запрещает клонирования исключения

    final public  function getMessage();        // сообщение исключения
    final public  function getCode();           // код исключения
    final public  function getFile();           // файл, где выброшено исключение
    final public  function getLine();           // строка, на которой выброшено исключение
    final public  function getTrace();          // массив backtrace()
    final public  function getPrevious();       // предыдущее исключение
    final public  function getTraceAsString();  // отформатированная строка трассировки

    // Переопределяемый
    public function __toString();               // отформатированная строка для отображения
}
?>
]]>
   </programlisting>
  </example>
  <para>
   Если класс, наследуемый от Exception переопределяет <link
   linkend="language.oop5.decon">конструктор</link>, необходимо вызвать в
   конструкторе <link linkend="language.oop5.paamayim-nekudotayim">parent::__construct()</link>, чтобы быть уверенным, что все доступные данные
   были правильно присвоены. Метод <link linkend="language.oop5.magic">__toString()</link>
   может быть переопределён, чтобы обеспечить нужный вывод, когда объект
   преобразовывается в строку.
  </para>
  <note>
   <para>
    Исключения нельзя клонировать.
    Попытка <link linkend="language.oop5.cloning">клонировать</link>
    исключение приведёт к неисправимой ошибке <constant>E_ERROR</constant>.
   </para>
  </note>
  <example>
   <title>Наследование класса Exception</title>
   <programlisting role="php">
<![CDATA[
<?php
/**
 * Определим свой класс исключения
 */
class MyException extends Exception
{
    // Переопределим исключение так, что параметр message станет обязательным
    public function __construct($message, $code = 0, Throwable $previous = null) {
        // некоторый код

        // убедитесь, что все передаваемые параметры верны
        parent::__construct($message, $code, $previous);
    }

    // Переопределим строковое представление объекта.
    public function __toString() {
        return __CLASS__ . ": [{$this->code}]: {$this->message}\n";
    }

    public function customFunction() {
        echo "Мы можем определять новые методы в наследуемом классе\n";
    }
}


/**
 * Создадим класс для тестирования исключения
 */
class TestException
{
    public $var;

    const THROW_NONE    = 0;
    const THROW_CUSTOM  = 1;
    const THROW_DEFAULT = 2;

    function __construct($avalue = self::THROW_NONE) {

        switch ($avalue) {
            case self::THROW_CUSTOM:
                // Выбрасываем собственное исключение
                throw new MyException('1 - неправильный параметр', 5);
                break;

            case self::THROW_DEFAULT:
                // Выбрасываем встроеное исключение
                throw new Exception('2 - недопустимый параметр', 6);
                break;

            default:
                // Никаких исключений, объект будет создан.
                $this->var = $avalue;
                break;
        }
    }
}

// Пример 1
try {
    $o = new TestException(TestException::THROW_CUSTOM);
} catch (MyException $e) {      // Будет перехвачено
    echo "Поймано собственное переопределённое исключение\n", $e;
    $e->customFunction();
} catch (Exception $e) {        // Будет пропущено
    echo "Поймано встроенное исключение\n", $e;
}

// Отсюда будет продолжено выполнение программы
var_dump($o); // Null
echo "\n\n";


// Пример 2
try {
    $o = new TestException(TestException::THROW_DEFAULT);
} catch (MyException $e) {      // Тип исключения не совпадёт
    echo "Поймано переопределённое исключение\n", $e;
    $e->customFunction();
} catch (Exception $e) {        // Будет перехвачено
    echo "Перехвачено встроенное исключение\n", $e;
}

// Отсюда будет продолжено выполнение программы
var_dump($o); // Null
echo "\n\n";


// Пример 3
try {
    $o = new TestException(TestException::THROW_CUSTOM);
} catch (Exception $e) {        // Будет перехвачено
    echo "Поймано встроенное исключение\n", $e;
}

// Продолжение исполнения программы
var_dump($o); // Null
echo "\n\n";


// Пример 4
try {
    $o = new TestException();
} catch (Exception $e) {        // Будет пропущено, т.к. исключение не выбрасывается
    echo "Поймано встроенное исключение\n", $e;
}

// Продолжение выполнения программы
var_dump($o); // TestException
echo "\n\n";
?>
]]>
   </programlisting>
  </example>
 </sect1>

</chapter>
<!-- Keep this comment at the end of the file
Local variables:
mode: sgml
sgml-omittag:t
sgml-shorttag:t
sgml-minimize-attributes:nil
sgml-always-quote-attributes:t
sgml-indent-step:1
sgml-indent-data:t
indent-tabs-mode:nil
sgml-parent-document:nil
sgml-default-dtd-file:"~/.phpdoc/manual.ced"
sgml-exposed-tags:nil
sgml-local-catalogs:nil
sgml-local-ecat-files:nil
End:
vim600: syn=xml fen fdm=syntax fdl=2 si
vim: et tw=78 syn=sgml
vi: ts=1 sw=1
-->
